Workbook

Sheet Sheet1
A3: Row Labels | B3: Count of Pillar
A4: A. Emergency preparedness & response | B4: 8
A5: B. Routine service & activity monitoring | B5: 16
A6: C. Reference & baseline data | B6: 7
A7: D. Assessment & analysis | B7: 5
A8: E. Strategy, funding & coordination | B8: 8
A9: F. Capacity building & partner support | B9: 5
A10: G. Coordination & representation | B10: 8
A11: Grand Total | B11: 57

Sheet Work Plan
A1: SCCCM Sector - Information Management Work Plan
A2: Shelter & NFI | Camp Coordination and Camp Management | Site Planning & Site Development - IM systems, products, capacity building and coordination supporting evidence-based response
A4: Ref | B4: Pillar | C4: IM system / dataset | D4: AoR | E4: End product | F4: Purpose | G4: Key message | H4: Frequency | I4: Data source / provider | J4: Primary audience | K4: Dissemination channel | L4: Responsible | M4: Status
A5: A1 | B5: A. Emergency preparedness & response | C5: Daily Incident Reporting | D5: CCCM / All | E5: Daily incident report, daily dataset & Daily Incident Dashboard | F5: Capture key information within the first 24 hours of an incident in all 33 camps so response can be triggered immediately. | G5: What happened, where, how many households and individuals were affected, and what immediate assistance is required. | H5: Daily | I5: Camp Focal Points / SMS agency via KoBo; cleaned by IOM NPM | J5: SCCCM partners, UNHCR IM, RRRC/CiC, ISCG | K5: Incident Report & Dataset receiver email groups; dashboard | L5: Sector IMO (oversight); IOM NPM (collection) | M5: Established
A6: A2 | B6: A. Emergency preparedness & response | C6: Rapid Damage Verification (RDV) | D6: Shelter / NFI | E6: Consolidated RDV dataset and damage-grade analysis | F6: Verify structural damage to shelters and camp infrastructure after fire, landslide or monsoon shocks to prioritise emergency repair. | G6: Which households sit in which damage grade, and the resulting shelter repair caseload by camp. | H6: Monthly | I6: IOM, UNHCR, BDRCS (moving to all-partner reporting) | J6: Shelter WG, SAG, partners, donors | K6: Email, ShareDrive, Shelter WG meeting | L6: Sector IMO; AoR focal points | M6: Established
A7: A3 | B7: A. Emergency preparedness & response | C7: Displacement Tracker | D7: CCCM | E7: Displacement tracking dataset and situation snapshot | F7: Track population movement and temporary displacement when a cyclone or major event occurs. | G7: How many people are displaced, from where to where, and what they need first. | H7: Event-triggered | I7: SMS agencies, Camp Focal Points | J7: SAG, ISCG, RRRC, partners | K7: Email, situation snapshot | L7: Sector IMO | M7: Template ready - activate on trigger
A8: A4 | B8: A. Emergency preparedness & response | C8: Cyclone Prepositioned Stock | D8: NFI / Shelter | E8: Prepositioned stock snapshot and readiness dashboard | F8: Show emergency response readiness before and during cyclone season. | G8: What emergency shelter and NFI stock is available, where it is held, and whether it meets the contingency target. | H8: Monthly | I8: BDRCS, IOM, UNHCR (expanding to all partners) | J8: SAG, NFI WG, EPRWG, donors | K8: Email, ShareDrive | L8: Sector IMO; NFI focal point | M8: Established - coverage expanding
A9: A5 | B9: A. Emergency preparedness & response | C9: EPR Readiness Checklist | D9: All | E9: Partner emergency preparedness readiness matrix | F9: Confirm partner-level preparedness ahead of the monsoon and cyclone season. | G9: Which partners are response-ready and where the preparedness gaps sit. | H9: Annual | I9: All SCCCM partners | J9: SAG, EPRWG, partners | K9: Email, coordination meeting | L9: Sector IMO with Coordinator | M9: Established
A10: A6 | B10: A. Emergency preparedness & response | C10: Joint Needs Assessment (JNA 4-hour / 72-hour) | D10: CCCM / All | E10: JNA dataset and first-phase rapid analysis | F10: Produce first-phase needs evidence within hours of a major event, using the questionnaire already agreed across sectors. | G10: What is needed, where and for how many people, within the first 72 hours. | H10: Event-triggered | I10: Camp focal points; collection by IOM NPM | J10: RCP, SAG, EPRWG, partners | K10: Flash report and dataset to receiver groups | L10: IOM NPM; Sector IMO | M10: Template ready - activate on trigger
A11: A7 | B11: A. Emergency preparedness & response | C11: Prepositioned stock mapping | D11: NFI / Shelter | E11: Stock preposition map and shortfall note | F11: Show where emergency stock sits relative to where the hazard is, so gaps are visible before the season, not during it. | G11: Whether prepositioned shelter and NFI stock is placed where the risk is, and the shortfall by camp. | H11: Monthly | I11: Contingency stock update (A4) | J11: SAG, NFI WG, EPRWG, donors | K11: Email, ShareDrive, on request | L11: Sector IMO; NFI focal point | M11: Established
A12: A8 | B12: A. Emergency preparedness & response | C12: Seasonal readiness reporting (monsoon and cyclone) | D12: All | E12: Weekly readiness snapshot during the season | F12: Move preparedness reporting from monthly to weekly while the hazard window is open, so the sector knows its own capacity in real time. | G12: Stock, capacity and camp-level readiness ahead of and during each weather event. | H12: Seasonal | I12: Partner stock and capacity data; EPRWG | J12: EPRWG, SAG, partners, RRRC | K12: Email, readiness note, coordination meeting | L12: Sector IMO; NFI focal point | M12: Established
A13: B1 | B13: B. Routine service & activity monitoring | C13: S-CCCM 5W activity reporting | D13: All | E13: Consolidated 5W dataset, monthly activity analysis, RCP submission | F13: Maintain the single authoritative record of who is doing what, where, when and for whom across the sector. | G13: Coverage, reach and gaps by camp, activity and partner - the backbone of evidence-based programming. | H13: Monthly | I13: All SCCCM partners via reporting template | J13: RCP, SAG, Working Groups, partners, donors | K13: Email request, ShareDrive, RCP submission | L13: Sector IMO | M13: Established
A14: B2 | B14: B. Routine service & activity monitoring | C14: Cash for Work (CfW) reporting | D14: CCCM / SP-SD | E14: Consolidated CfW dataset submitted alongside the 5W | F14: Track Cash for Work volume, participation and geographic coverage. | G14: How many people accessed CfW, in which camps, and how equitably opportunities are spread. | H14: Monthly | I14: Partners implementing CfW | J14: RCP, SAG, partners | K14: Email, ShareDrive | L14: Sector IMO | M14: Established
A15: B3 | B15: B. Routine service & activity monitoring | C15: Shelter & NFI stock monitoring | D15: Shelter / NFI | E15: Monthly shelter and NFI stock snapshot | F15: Keep visibility of available and pipeline stock so distribution can be planned against real availability. | G15: What stock is available now, what is in the pipeline, and where shortfalls will bite first. | H15: Monthly | I15: Partners holding stock | J15: NFI WG, Shelter WG, SAG | K15: Email, ShareDrive | L15: Sector IMO | M15: Established
... A61: G8 | B61: G. Coordination & representation | C61: Joint guidance notes with other sectors | D61: All | E61: Agreed guidance notes, such as the volunteer guidance note with LSDS | F61: Settle recurring cross-sector questions once, in writing, instead of case by case. | G61: The agreed position and how partners should apply it. | H61: Periodic | I61: Sector team with the counterpart sector | J61: Partners, Working Groups | K61: Guidance note circulated and published | L61: Sector IMO; Sector Coordinator | M61: In development
A63: Sources: SCCCM Sector IM handover note; the sector IM annual workplan; the 2026 SCCCM 5W dataset; the 2026 and 2027 JRP log frames. Rows marked "To establish" or "In development" are not yet producing regular output and carry an action for the coming cycle. Refs run A1-A8 emergency, B1-B16 routine monitoring, C1-C7 reference data, D1-D5 assessment, E1-E8 strategy and planning, F1-F5 capacity building, G1-G8 coordination and representation.

Sheet Reporting Calendar
A1: Reporting calendar & monthly rhythm
A2: When each product is produced. Monthly items repeat every month; the working rhythm below shows the sequence within a month.
A3: Ref | B3: Product | C3: Frequency | D3: Jan | E3: Feb | F3: Mar | G3: Apr | H3: May | I3: Jun | J3: Jul | K3: Aug | L3: Sep | M3: Oct | N3: Nov | O3: Dec
A4: A1 | B4: Daily Incident Reporting | C4: Daily | D4: • | E4: • | F4: • | G4: • | H4: • | I4: • | J4: • | K4: • | L4: • | M4: • | N4: • | O4: •
A5: A2 | B5: Rapid Damage Verification (RDV) | C5: Monthly | D5: • | E5: • | F5: • | G5: • | H5: • | I5: • | J5: • | K5: • | L5: • | M5: • | N5: • | O5: •
A6: A3 | B6: Displacement Tracker | C6: Event-triggered
A7: A4 | B7: Cyclone Prepositioned Stock | C7: Monthly | D7: • | E7: • | F7: • | G7: • | H7: • | I7: • | J7: • | K7: • | L7: • | M7: • | N7: • | O7: •
A8: A5 | B8: EPR Readiness Checklist | C8: Annual | G8: •
A9: A6 | B9: Joint Needs Assessment (JNA 4-hour / 72-hour) | C9: Event-triggered
A10: A7 | B10: Prepositioned stock mapping | C10: Monthly | D10: • | E10: • | F10: • | G10: • | H10: • | I10: • | J10: • | K10: • | L10: • | M10: • | N10: • | O10: •
A11: A8 | B11: Seasonal readiness reporting (monsoon and cyclone) | C11: Seasonal | I11: • | J11: • | K11: • | L11: • | M11: •
A12: B1 | B12: S-CCCM 5W activity reporting | C12: Monthly | D12: • | E12: • | F12: • | G12: • | H12: • | I12: • | J12: • | K12: • | L12: • | M12: • | N12: • | O12: •
A13: B2 | B13: Cash for Work (CfW) reporting | C13: Monthly | D13: • | E13: • | F13: • | G13: • | H13: • | I13: • | J13: • | K13: • | L13: • | M13: • | N13: • | O13: •
A14: B3 | B14: Shelter & NFI stock monitoring | C14: Monthly | D14: • | E14: • | F14: • | G14: • | H14: • | I14: • | J14: • | K14: • | L14: • | M14: • | N14: • | O14: •
A15: B4 | B15: Shelter Progress Tracker | C15: Monthly | D15: • | E15: • | F15: • | G15: • | H15: • | I15: • | J15: • | K15: • | L15: • | M15: • | N15: • | O15: •
A16: B5 | B16: Shelter activities mapping | C16: Monthly | D16: • | E16: • | F16: • | G16: • | H16: • | I16: • | J16: • | K16: • | L16: • | M16: • | N16: • | O16: •
A17: B6 | B17: SMART service monitoring | C17: Monthly | D17: • | E17: • | F17: • | G17: • | H17: • | I17: • | J17: • | K17: • | L17: • | M17: • | N17: • | O17: •
A18: B7 | B18: Capacity Sharing Initiative (CSI) reporting | C18: Monthly | D18: • | E18: • | F18: • | G18: • | H18: • | I18: • | J18: • | K18: • | L18: • | M18: • | N18: • | O18: •
A19: B8 | B19: M&E indicator matrix | C19: Monthly | D19: • | E19: • | F19: • | G19: • | H19: • | I19: • | J19: • | K19: • | L19: • | M19: • | N19: • | O19: •
A20: B9 | B20: LLL dashboard | C20: Monthly | D20: • | E20: • | F20: • | G20: • | H20: • | I20: • | J20: • | K20: • | L20: • | M20: • | N20: • | O20: •
A21: B10 | B21: Site Management (SM) 5W reporting | C21: Monthly | D21: • | E21: • | F21: • | G21: • | H21: • | I21: • | J21: • | K21: • | L21: • | M21: • | N21: • | O21: •
A22: B11 | B22: Site Development (SD) 4W reporting | C22: Monthly | D22: • | E22: • | F22: • | G22: • | H22: • | I22: • | J22: • | K22: • | L22: • | M22: • | N22: • | O22: •
A23: B12 | B23: Merged sector interactive dashboard | C23: Monthly | D23: • | E23: • | F23: • | G23: • | H23: • | I23: • | J23: • | K23: • | L23: • | M23: • | N23: • | O23: •
... A28: C1 | B28: Population data | C28: Monthly | D28: • | E28: • | F28: • | G28: • | H28: • | I28: • | J28: • | K28: • | L28: • | M28: • | N28: • | O28: •
A29: C2 | B29: Camp Focal Point contact management | C29: Bi-monthly | D29: • | F29: • | H29: • | J29: • | L29: • | N29: •
A30: C3 | B30: Operational presence & AoR mapping | C30: Quarterly | F30: • | I30: • | L30: • | O30: •
A31: C4 | B31: Facility mapping & monitoring | C31: Annual | N31: •
A32: C5 | B32: GIS repository | C32: Continuous | D32: • | E32: • | F32: • | G32: • | H32: • | I32: • | J32: • | K32: • | L32: • | M32: • | N32: • | O32: •
A33: C6 | B33: Block-level hazard risk mapping | C33: Annual | G33: •
A34: C7 | B34: MSSP / site planning dashboard | C34: Quarterly | F34: • | I34: • | L34: • | O34: •
A35: D1 | B35: Inter-Sector Needs Assessment (ISNA) | C35: Annual | N35: •
A36: D2 | B36: Shelter Performance Standard (SPS) assessment | C36: Periodic | I36: • | O36: •
A37: D3 | B37: Vacant space & site planning evidence | C37: Quarterly | F37: • | I37: • | L37: • | O37: •
A38: D4 | B38: NFI assessment | C38: Annual | L38: •
A39: D5 | B39: Post-assistance and post-distribution monitoring | C39: Quarterly | F39: • | I39: • | L39: • | O39: •
A40: E1 | B40: JRP planning & financial tracking | C40: Quarterly | F40: • | I40: • | L40: • | O40: •
A41: E2 | B41: Coordination documentation | C41: Monthly | D41: • | E41: • | F41: • | G41: • | H41: • | I41: • | J41: • | K41: • | L41: • | M41: • | N41: • | O41: •
A42: E3 | B42: IM product plan & website publication | C42: Annual | N42: •
A43: E4 | B43: Monthly submission package to RCP | C43: Monthly | D43: • | E43: • | F43: • | G43: • | H43: • | I43: • | J43: • | K43: • | L43: • | M43: • | N43: • | O43: •
A44: E5 | B44: Log frame quality assurance | C44: Annual | K44: • | L44: •
...

Sheet Roles & Data Quality
A1: Roles, data quality and data responsibility
A2: Applied to every dataset and product in this work plan, every cycle.
A4: Roles
A5: Sector IMO | B5: Owns the IM work plan. Runs collection cycles, consolidates and quality-checks datasets, produces and publishes products, trains partners and represents the sector in IMAWG.
A6: Sector Coordinator | B6: Sets analytical priorities, endorses products before release, chairs the fora where findings are presented, escalates persistent non-reporting.
A7: AoR focal points (SM, SD, Shelter, NFI) | B7: Validate AoR-specific data, confirm camp focal point lists, quality-assure technical content and resolve partner queries in their area.
A8: Reporting partners | B8: Submit complete, on-time data using the agreed templates; nominate and maintain a reporting focal point and a named backup.
A9: IOM NPM | B9: Collects and cleans daily incident data; runs JNA; supports assessment collection; provides drone imagery, DEM and hazard risk products; hosts facility and MSSP dashboards.
A10: UNHCR IM Unit | B10: Provides population data, Power BI workspace and publication support, and shared software licences.
A11: RCP | B11: Sets inter-sector submission deadlines, consolidates the response-level picture and runs the periodic funding exercise.
A13: Data quality assurance - applied at every collection cycle
A14: 1. Completeness | B14: Check every expected partner has reported; log and follow up non-reporters before consolidation rather than after publication.
A15: 2. Validity | B15: Enforce controlled vocabularies (camp, block, partner, activity, unit) through KoBo constraints and cascading choice lists rather than by correcting afterwards.
A16: 3. Consistency | B16: Reconcile against the agreed population baseline and the previous cycle; for implementing partners, reconcile project reporting with the sector 5W.
A17: 4. Plausibility | B17: Flag logical impossibilities - end date before start date, reach above camp population, reached above target, camp-status indicators repeating monthly.
A18: 5. Traceability | B18: Version every dataset with a date stamp; keep raw submissions unaltered alongside the cleaned master and log every correction.
A19: 6. Documentation | B19: Publish figures with their source, reference period, unit and known limitations, so users can judge fitness for purpose.
A21: Data responsibility
A22: Personal data | B22: No personally identifiable information is collected or shared through sector products. Assessment datasets are anonymised before sharing.
A23: Aggregation | B23: Data is published at camp or block level; no household-level disclosure.
A24: Access | B24: Datasets are shared through managed sector email groups and controlled cloud storage, not open links.
A25: Classification | B25: Each product is public, partners-only or internal. Nothing moves to a wider class without the Sector Coordinator.
A26: Purpose limitation | B26: Data is collected only where a defined product or decision requires it. If no product uses an indicator, it is retired from the template.
A28: How this plan supports evidence-based response
A29: Common baselines | B29: One population figure, one camp and block reference and one partner list mean every product is comparable.
A30: Predictable cycles | B30: Partners know what is requested and when, which raises reporting rates and shortens turnaround.
A31: Gap visibility | B31: 5W, facility mapping and hazard risk read together show where need, presence and risk do not overlap - the basis for reprioritisation.
A32: Decision linkage | B32: Every product carries a key message tied to a decision forum (SAG, Working Group, Task Force) rather than being published for its own sake.
A33: Feedback loop | B33: Findings return to partners through the Working Groups, so data providers see how their submissions were used.
A34: Capacity, not correction | B34: Partners are trained and supported to report correctly (pillar F) instead of having their data corrected centrally every month.

Sheet Summary
A1: Work plan summary
A2: Counts are live formulas over the Work Plan sheet - they update if rows are added or edited.
A4: By frequency
A5: Daily | B5: =COUNTIF('Work Plan'!$H$5:$H$61,A5) -> 2
A6: Monthly | B6: =COUNTIF('Work Plan'!$H$5:$H$61,A6) -> 28
A7: Bi-monthly | B7: =COUNTIF('Work Plan'!$H$5:$H$61,A7) -> 1
A8: Quarterly | B8: =COUNTIF('Work Plan'!$H$5:$H$61,A8) -> 6
A9: Annual | B9: =COUNTIF('Work Plan'!$H$5:$H$61,A9) -> 9
A10: Periodic | B10: =COUNTIF('Work Plan'!$H$5:$H$61,A10) -> 6
A11: Seasonal | B11: =COUNTIF('Work Plan'!$H$5:$H$61,A11) -> 1
A12: Continuous | B12: =COUNTIF('Work Plan'!$H$5:$H$61,A12) -> 1
A13: Event-triggered | B13: =COUNTIF('Work Plan'!$H$5:$H$61,A13) -> 2
A14: On request | B14: =COUNTIF('Work Plan'!$H$5:$H$61,A14) -> 1
A15: Total | B15: =SUM(B5:B14) -> 57
A17: By pillar
A18: A. Emergency preparedness & response | B18: =COUNTIF('Work Plan'!$B$5:$B$61,A18) -> 8
A19: B. Routine service & activity monitoring | B19: =COUNTIF('Work Plan'!$B$5:$B$61,A19) -> 16
A20: C. Reference & baseline data | B20: =COUNTIF('Work Plan'!$B$5:$B$61,A20) -> 7
A21: D. Assessment & analysis | B21: =COUNTIF('Work Plan'!$B$5:$B$61,A21) -> 5
A22: E. Strategy, funding & coordination | B22: =COUNTIF('Work Plan'!$B$5:$B$61,A22) -> 8
A23: F. Capacity building & partner support | B23: =COUNTIF('Work Plan'!$B$5:$B$61,A23) -> 5
A24: G. Coordination & representation | B24: =COUNTIF('Work Plan'!$B$5:$B$61,A24) -> 8
A25: Total | B25: =SUM(B18:B24) -> 57
A27: By status
A28: Established / operating | B28: =COUNTIF('Work Plan'!$M$5:$M$61,"Established*") -> 42
A29: Baseline done, next cycle TBC | B29: =COUNTIF('Work Plan'!$M$5:$M$61,"Baseline done*") -> 1
A30: In progress (assessment cycle) | B30: =COUNTIF('Work Plan'!$M$5:$M$61,"In progress*") -> 1
A31: In development / pilot | B31: =COUNTIF('Work Plan'!$M$5:$M$61,"In development*") -> 5
A32: Under design | B32: =COUNTIF('Work Plan'!$M$5:$M$61,"Under design*") -> 1
A33: Template ready (on trigger) | B33: =COUNTIF('Work Plan'!$M$5:$M$61,"Template ready*") -> 2
A34: To establish | B34: =COUNTIF('Work Plan'!$M$5:$M$61,"To establish*") -> 5
A35: Subtotal (must equal total below) | B35: =SUM(B28:B34) -> 57
A37: Total systems and activities in plan | B37: =COUNTA('Work Plan'!$A$5:$A$61) -> 57
A39: New in this version
A40: A6-A8 emergency: JNA, prepositioned stock mapping, seasonal readiness reporting
A41: B10-B16 routine: SM 5W and SD 4W as separate streams, merged dashboard, host community reporting, NFI and annual shelter trackers, incident dashboard
A42: C7 MSSP / site planning dashboard
A43: D4-D5 NFI assessment and post-distribution monitoring
A44: E4-E8 RCP submission package, log frame QA, template revision, field verification, ad-hoc requests
A45: F1-F5 capacity building: induction, refreshers, KoBo and SMART training, one-to-one follow-up
...
